#VRML_SIM R2019b utf8
WorldInfo {
  basicTimeStep 16
  contactProperties [
    ContactProperties {
      material2 "dog"
    }
  ]
}
Viewpoint {
  orientation -0.0063886957607947855 -0.9888096300971353 -0.149045966042837 3.0977108911638376
  position -0.2197228050910729 1.0664674947282815 -3.580247565412533
}
TexturedBackground {
}
TexturedBackgroundLight {
}
RectangleArena {
  translation 0 -0.3 0.19
  rotation 1 0 0 4.692820414042842e-06
  floorSize 4 4
}
DEF DOT_GO Robot {
  translation 0 0.12 0.01
  children [
    DEF HIP3 Hinge2Joint {
      jointParameters HingeJointParameters {
        anchor -0.2 0 -0.1
      }
      jointParameters2 JointParameters {
      }
      device [
        PositionSensor {
          name "hip3x_pos"
        }
        RotationalMotor {
          name "hip3x"
          maxTorque 100
        }
      ]
      device2 [
        PositionSensor {
          name "hip3z_pos"
        }
        RotationalMotor {
          name "hip3z"
          maxTorque 100
        }
      ]
      endPoint Solid {
        translation -0.20000608686423835 -4.766681333544348e-05 -0.09999999754399529
        rotation -0.05596291416413469 -0.9984328481366475 2.449044735558207e-09 1.1151007970493858e-07
        children [
          DEF KNEE3 HingeJoint {
            jointParameters HingeJointParameters {
              axis 0 0 1
              anchor 0 -0.15 0
            }
            device [
              PositionSensor {
                name "knee3_pos"
              }
              RotationalMotor {
                name "knee3"
                maxTorque 100
              }
            ]
            endPoint Solid {
              translation 0 -0.15 0
              rotation 0 0 1 0
              children [
                DEF KNEE1_GROUP Group {
                  children [
                    DEF FOOT Transform {
                      translation 0 -0.15 0
                      rotation 1 0 0 1.5707
                      children [
                        Shape {
                          appearance PBRAppearance {
                            baseColor 0.180392 0.203922 0.211765
                            roughness 0.5
                            metalness 0
                          }
                          geometry Cylinder {
                            height 0.05
                            radius 0.03
                          }
                        }
                      ]
                    }
                    DEF SPRING Transform {
                      translation 0 -0.075 0
                      children [
                        Shape {
                          appearance PBRAppearance {
                            baseColor 0 0.8 0
                            roughness 0.5
                          }
                          geometry Cylinder {
                            height 0.15
                            radius 0.015
                          }
                        }
                      ]
                    }
                    DEF KNEE Transform {
                      rotation 1 0 0 1.5707
                      children [
                        Shape {
                          appearance PBRAppearance {
                            baseColor 0.8 0 0
                            roughness 0.5
                          }
                          geometry Cylinder {
                            height 0.03
                            radius 0.03
                          }
                        }
                      ]
                    }
                  ]
                }
              ]
              boundingObject USE KNEE1_GROUP
              physics Physics {
              }
            }
          }
          DEF HIP3_GROUP Group {
            children [
              DEF FEMUR_TRANS Transform {
                translation 0 -0.075 0
                children [
                  Shape {
                    appearance PBRAppearance {
                      baseColor 0 0.8 0
                      roughness 0.5
                    }
                    geometry Cylinder {
                      height 0.15
                      radius 0.015
                    }
                  }
                ]
              }
              DEF HIP1_TRANS Transform {
                children [
                  Shape {
                    appearance PBRAppearance {
                      baseColor 0.8 0 0
                      roughness 0.5
                    }
                    geometry Sphere {
                      radius 0.03
                    }
                  }
                ]
              }
            ]
          }
        ]
        name "hip3"
        boundingObject USE HIP3_GROUP
        physics Physics {
        }
      }
    }
    DEF HIP2 Hinge2Joint {
      jointParameters HingeJointParameters {
        anchor -0.2 0 0.1
      }
      jointParameters2 JointParameters {
      }
      device [
        PositionSensor {
          name "hip2x_pos"
        }
        RotationalMotor {
          name "hip2x"
          maxTorque 100
        }
      ]
      device2 [
        PositionSensor {
          name "hip2z_pos"
        }
        RotationalMotor {
          name "hip2z"
          maxTorque 100
        }
      ]
      endPoint Solid {
        translation -0.19999590437609466 -4.300726290571177e-05 0.09999999687727783
        rotation 0.5048173017587092 -0.8632262112824518 8.662308903962538e-10 3.734220292014386e-07
        children [
          DEF KNEE2 HingeJoint {
            jointParameters HingeJointParameters {
              axis 0 0 1
              anchor 0 -0.15 0
            }
            device [
              PositionSensor {
                name "knee2_pos"
              }
              RotationalMotor {
                name "knee2"
                maxTorque 100
              }
            ]
            endPoint Solid {
              translation 0 -0.15 0
              rotation 0 0 1 0
              children [
                DEF KNEE2_GROUP Group {
                  children [
                    DEF FOOT Transform {
                      translation 0 -0.15 0
                      rotation 1 0 0 1.5707
                      children [
                        Shape {
                          appearance PBRAppearance {
                            baseColor 0.180392 0.203922 0.211765
                            roughness 0.5
                            metalness 0
                          }
                          geometry Cylinder {
                            height 0.05
                            radius 0.03
                          }
                        }
                      ]
                    }
                    DEF SPRING Transform {
                      translation 0 -0.075 0
                      children [
                        Shape {
                          appearance PBRAppearance {
                            baseColor 0 0.8 0
                            roughness 0.5
                          }
                          geometry Cylinder {
                            height 0.15
                            radius 0.015
                          }
                        }
                      ]
                    }
                    DEF KNEE Transform {
                      rotation 1 0 0 1.5707
                      children [
                        Shape {
                          appearance PBRAppearance {
                            baseColor 0.8 0 0
                            roughness 1
                          }
                          geometry Cylinder {
                            height 0.03
                            radius 0.03
                          }
                        }
                      ]
                    }
                  ]
                }
              ]
              boundingObject USE KNEE2_GROUP
              physics Physics {
              }
            }
          }
          DEF HIP2_GROUP Group {
            children [
              DEF FEMUR_TRANS Transform {
                translation 0 -0.075 0
                children [
                  Shape {
                    appearance PBRAppearance {
                      baseColor 0 0.8 0
                      roughness 0.5
                    }
                    geometry Cylinder {
                      height 0.15
                      radius 0.015
                    }
                  }
                ]
              }
              DEF HIP2_TRANS Transform {
                children [
                  Shape {
                    appearance PBRAppearance {
                      baseColor 0.8 0 0
                      roughness 0.5
                    }
                    geometry Sphere {
                      radius 0.03
                    }
                  }
                ]
              }
            ]
          }
        ]
        name "hip2"
        boundingObject USE HIP2_GROUP
        physics Physics {
        }
      }
    }
    DEF HIP1 Hinge2Joint {
      jointParameters HingeJointParameters {
        anchor 0.2 0 -0.1
      }
      jointParameters2 JointParameters {
      }
      device [
        PositionSensor {
          name "hip1x_pos"
        }
        RotationalMotor {
          name "hip1x"
          maxTorque 100
        }
      ]
      device2 [
        PositionSensor {
          name "hip1z_pos"
        }
        RotationalMotor {
          name "hip1z"
          maxTorque 100
        }
      ]
      endPoint Solid {
        translation 0.20000228302022832 -1.9151218807147833e-05 -0.0999999994269053
        rotation 0.28194453531958596 -0.9594307056809381 -1.2344127834538342e-09 1.1151007970493858e-07
        children [
          DEF KNEE1 HingeJoint {
            jointParameters HingeJointParameters {
              axis 0 0 1
              anchor 0 -0.15 0
            }
            device [
              PositionSensor {
                name "knee1_pos"
              }
              RotationalMotor {
                name "knee1"
                maxTorque 100
              }
            ]
            endPoint Solid {
              translation 0 -0.15 0
              rotation 0 0 1 0
              children [
                DEF KNEE1_GROUP Group {
                  children [
                    DEF FOOT Transform {
                      translation 0 -0.15 0
                      rotation 1 0 0 1.5707
                      children [
                        Shape {
                          appearance PBRAppearance {
                            baseColor 0.180392 0.203922 0.211765
                            roughness 0.5
                            metalness 0
                          }
                          geometry Cylinder {
                            height 0.05
                            radius 0.03
                          }
                        }
                      ]
                    }
                    DEF SPRING Transform {
                      translation 0 -0.075 0
                      children [
                        Shape {
                          appearance PBRAppearance {
                            baseColor 0 0.8 0
                            roughness 0.5
                          }
                          geometry Cylinder {
                            height 0.15
                            radius 0.015
                          }
                        }
                      ]
                    }
                    DEF KNEE Transform {
                      rotation 1 0 0 1.5707
                      children [
                        Shape {
                          appearance PBRAppearance {
                            baseColor 0.8 0 0
                            roughness 1
                          }
                          geometry Cylinder {
                            height 0.03
                            radius 0.03
                          }
                        }
                      ]
                    }
                  ]
                }
              ]
              boundingObject USE KNEE1_GROUP
              physics Physics {
              }
            }
          }
          DEF HIP1_GROUP Group {
            children [
              DEF FEMUR_TRANS Transform {
                translation 0 -0.075 0
                children [
                  Shape {
                    appearance PBRAppearance {
                      baseColor 0 0.8 0
                      roughness 0.5
                    }
                    geometry Cylinder {
                      height 0.15
                      radius 0.015
                    }
                  }
                ]
              }
              DEF HIP1_TRANS Transform {
                children [
                  Shape {
                    appearance PBRAppearance {
                      baseColor 0.8 0 0
                      roughness 0.5
                    }
                    geometry Sphere {
                      radius 0.03
                    }
                  }
                ]
              }
            ]
          }
        ]
        name "hip1"
        boundingObject USE HIP1_GROUP
        physics Physics {
        }
      }
    }
    DEF HIP0 Hinge2Joint {
      jointParameters HingeJointParameters {
        anchor 0.2 0 0.1
      }
      jointParameters2 JointParameters {
      }
      device [
        PositionSensor {
          name "hip0x_pos"
        }
        RotationalMotor {
          name "hip0x"
          maxTorque 100
        }
      ]
      device2 [
        PositionSensor {
          name "hip0z_pos"
        }
        RotationalMotor {
          name "hip0z"
          maxTorque 100
        }
      ]
      endPoint Solid {
        translation 0.200004 -7.48718e-06 0.1
        rotation -0.6315110604808886 0.7753668683212505 -1.3688848147934803e-08 1.5769906706002898e-07
        children [
          DEF KNEE0 HingeJoint {
            jointParameters HingeJointParameters {
              axis 0 0 1
              anchor 0 -0.15 0
            }
            device [
              PositionSensor {
                name "knee0_pos"
              }
              RotationalMotor {
                name "knee0"
                maxTorque 100
              }
            ]
            endPoint Solid {
              translation 0 -0.15 0
              rotation 0 0 1 0
              children [
                DEF KNEE0_GROUP Group {
                  children [
                    DEF KNEE Transform {
                      rotation 1 0 0 1.5707
                      children [
                        DEF KNEE_SHAPE Shape {
                          appearance PBRAppearance {
                            baseColor 0.8 0 0
                            roughness 0.5
                          }
                          geometry Cylinder {
                            height 0.03
                            radius 0.03
                          }
                        }
                      ]
                    }
                    DEF FOOT0 Transform {
                      translation 0 -0.15 0
                      rotation 1 0 0 1.5707
                      children [
                        Shape {
                          appearance PBRAppearance {
                            baseColor 0.180392 0.203922 0.211765
                            roughness 0.5
                            metalness 0.5
                          }
                          geometry Cylinder {
                            height 0.05
                            radius 0.03
                          }
                        }
                      ]
                    }
                    DEF SPRING Transform {
                      translation 0 -0.075 0
                      rotation 0 0 1 0
                      children [
                        Shape {
                          appearance PBRAppearance {
                            baseColor 0 0.8 0
                            roughness 0.5
                          }
                          geometry Cylinder {
                            height 0.15
                            radius 0.015
                          }
                        }
                      ]
                    }
                  ]
                }
              ]
              boundingObject USE KNEE0_GROUP
              physics Physics {
              }
            }
          }
          DEF HIP0_GROUP Group {
            children [
              DEF FEMUR_TRANS Transform {
                translation 0 -0.075 0
                children [
                  Shape {
                    appearance DEF LEG_APPEARANCE PBRAppearance {
                      baseColor 0 0.8 0
                      roughness 0.5
                    }
                    geometry Cylinder {
                      height 0.15
                      radius 0.015
                    }
                  }
                ]
              }
              DEF HIP_TRANS Transform {
                children [
                  DEF HIP_SHAPE Shape {
                    appearance DEF JOINT_APPEARANCE PBRAppearance {
                      baseColor 0.8 0 0
                      roughness 0.5
                    }
                    geometry Sphere {
                      radius 0.03
                    }
                  }
                ]
              }
            ]
          }
        ]
        name "hip0"
        boundingObject USE HIP0_GROUP
        physics Physics {
          centerOfMass [
            0 0 0
          ]
        }
      }
    }
    DEF BODY_SHAPE Shape {
      appearance DEF BODY_APPEARANCE PBRAppearance {
        baseColor 0.756863 0.490196 0.0666667
        roughness 0.5
        metalness 0.1
      }
      geometry Box {
        size 0.4 0.05 0.2
      }
    }
  ]
  name "dot_go"
  contactMaterial "dog"
  boundingObject USE BODY_SHAPE
  physics Physics {
    density 10
  }
  controller "quadruped_controller"
}
DEF WORKBANCH Solid {
  translation 0 -0.08 0
  children [
    DEF WORKBANCH_GROUP Group {
      children [
        DEF TOP Transform {
          translation 0 0.16 0
          children [
            Shape {
              appearance PBRAppearance {
                baseColor 0.333333 0.341176 0.32549
              }
              geometry Box {
                size 0.1 0.02 0.4
              }
            }
          ]
        }
        DEF BOTTOM Transform {
          translation 0 -0.2 0
          children [
            Shape {
              appearance PBRAppearance {
                baseColor 0.333333 0.341176 0.32549
              }
              geometry Box {
                size 0.5 0.05 0.5
              }
            }
          ]
        }
        DEF CYLINDER Shape {
          appearance PBRAppearance {
            baseColor 0.333333 0.341176 0.32549
            metalness 0
          }
          geometry Cylinder {
            height 0.34
            radius 0.06
          }
        }
      ]
    }
  ]
  boundingObject USE WORKBANCH_GROUP
  physics Physics {
    density 2000
  }
}
